[2025-05-21T18:19:04.323+0000] {local_task_job_runner.py:123} INFO - ::group::Pre task execution logs
[2025-05-21T18:19:04.392+0000] {taskinstance.py:2613} INFO - Dependencies all met for dep_context=non-requeueable deps ti=<TaskInstance: test_car_5_tg.process_file manual__2025-05-21T18:18:57.580086+00:00 [queued]>
[2025-05-21T18:19:04.427+0000] {taskinstance.py:2613} INFO - Dependencies all met for dep_context=requeueable deps ti=<TaskInstance: test_car_5_tg.process_file manual__2025-05-21T18:18:57.580086+00:00 [queued]>
[2025-05-21T18:19:04.430+0000] {taskinstance.py:2866} INFO - Starting attempt 1 of 2
[2025-05-21T18:19:04.486+0000] {taskinstance.py:2889} INFO - Executing <Task(PythonOperator): process_file> on 2025-05-21 18:18:57.580086+00:00
[2025-05-21T18:19:04.511+0000] {warnings.py:112} WARNING - /home/***/.local/lib/python3.12/site-packages/***/task/task_runner/standard_task_runner.py:70: DeprecationWarning: This process (pid=1029) is multi-threaded, use of fork() may lead to deadlocks in the child.
  pid = os.fork()

[2025-05-21T18:19:04.530+0000] {standard_task_runner.py:72} INFO - Started process 1031 to run task
[2025-05-21T18:19:04.531+0000] {standard_task_runner.py:104} INFO - Running: ['***', 'tasks', 'run', 'test_car_5_tg', 'process_file', 'manual__2025-05-21T18:18:57.580086+00:00', '--job-id', '13', '--raw', '--subdir', 'DAGS_FOLDER/test_car_5 _tg.py', '--cfg-path', '/tmp/tmpymdstfsm']
[2025-05-21T18:19:04.549+0000] {standard_task_runner.py:105} INFO - Job 13: Subtask process_file
[2025-05-21T18:19:04.751+0000] {task_command.py:467} INFO - Running <TaskInstance: test_car_5_tg.process_file manual__2025-05-21T18:18:57.580086+00:00 [running]> on host 0562d356b684
[2025-05-21T18:19:05.177+0000] {taskinstance.py:3132} INFO - Exporting env vars: AIRFLOW_CTX_DAG_OWNER='***' AIRFLOW_CTX_DAG_ID='test_car_5_tg' AIRFLOW_CTX_TASK_ID='process_file' AIRFLOW_CTX_EXECUTION_DATE='2025-05-21T18:18:57.580086+00:00' AIRFLOW_CTX_TRY_NUMBER='1' AIRFLOW_CTX_DAG_RUN_ID='manual__2025-05-21T18:18:57.580086+00:00'
[2025-05-21T18:19:05.182+0000] {taskinstance.py:731} INFO - ::endgroup::
[2025-05-21T18:19:05.286+0000] {test_car_5 _tg.py:138} INFO - >>> [START] process_file
[2025-05-21T18:19:05.292+0000] {test_car_5 _tg.py:141} INFO - Execution date: 2025-05-21 18:18:57.580086+00:00
[2025-05-21T18:19:06.204+0000] {base.py:84} INFO - Retrieving connection 'postgres_default'
[2025-05-21T18:19:06.218+0000] {test_car_5 _tg.py:106} ERROR - Error saving rate to DB: relation "cur_rate" does not exist
LINE 2:                             INSERT INTO cur_rate 
                                                ^

[2025-05-21T18:19:06.220+0000] {test_car_5 _tg.py:115} WARNING - Attempt 1 failed to get currency rate: relation "cur_rate" does not exist
LINE 2:                             INSERT INTO cur_rate 
                                                ^

[2025-05-21T18:19:06.222+0000] {test_car_5 _tg.py:117} INFO - Waiting 0.25 minutes before next attempt...
[2025-05-21T18:19:21.783+0000] {base.py:84} INFO - Retrieving connection 'postgres_default'
[2025-05-21T18:19:21.843+0000] {test_car_5 _tg.py:106} ERROR - Error saving rate to DB: relation "cur_rate" does not exist
LINE 2:                             INSERT INTO cur_rate 
                                                ^

[2025-05-21T18:19:21.865+0000] {test_car_5 _tg.py:115} WARNING - Attempt 2 failed to get currency rate: relation "cur_rate" does not exist
LINE 2:                             INSERT INTO cur_rate 
                                                ^

[2025-05-21T18:19:21.898+0000] {test_car_5 _tg.py:117} INFO - Waiting 0.25 minutes before next attempt...
[2025-05-21T18:19:34.995+0000] {local_task_job_runner.py:346} WARNING - State of this instance has been externally set to None. Terminating instance.
[2025-05-21T18:19:34.997+0000] {local_task_job_runner.py:245} INFO - ::endgroup::
[2025-05-21T18:19:35.000+0000] {process_utils.py:132} INFO - Sending 15 to group 1031. PIDs of all processes in the group: [1031]
[2025-05-21T18:19:35.001+0000] {process_utils.py:87} INFO - Sending the signal 15 to group 1031
[2025-05-21T18:19:35.002+0000] {taskinstance.py:3093} ERROR - Received SIGTERM. Terminating subprocesses.
[2025-05-21T18:19:35.020+0000] {taskinstance.py:3311} ERROR - Task failed with exception
Traceback (most recent call last):
  File "/opt/airflow/dags/test_car_5 _tg.py", line 96, in get_currency_rate
    cursor.execute("""
psycopg2.errors.UndefinedTable: relation "cur_rate" does not exist
LINE 2:                             INSERT INTO cur_rate 
                                                ^


During handling of the above exception, another exception occurred:

Traceback (most recent call last):
  File "/home/airflow/.local/lib/python3.12/site-packages/airflow/models/taskinstance.py", line 767, in _execute_task
    result = _execute_callable(context=context, **execute_callable_kwargs)
             ^^^^^^^^^^^^^^^^^^^^^^^^^^^^^^^^^^^^^^^^^^^^^^^^^^^^^^^^^^^^^
  File "/home/airflow/.local/lib/python3.12/site-packages/airflow/models/taskinstance.py", line 733, in _execute_callable
    return ExecutionCallableRunner(
           ^^^^^^^^^^^^^^^^^^^^^^^^
  File "/home/airflow/.local/lib/python3.12/site-packages/airflow/utils/operator_helpers.py", line 252, in run
    return self.func(*args, **kwargs)
           ^^^^^^^^^^^^^^^^^^^^^^^^^^
  File "/home/airflow/.local/lib/python3.12/site-packages/airflow/models/baseoperator.py", line 422, in wrapper
    return func(self, *args, **kwargs)
           ^^^^^^^^^^^^^^^^^^^^^^^^^^^
  File "/home/airflow/.local/lib/python3.12/site-packages/airflow/operators/python.py", line 238, in execute
    return_value = self.execute_callable()
                   ^^^^^^^^^^^^^^^^^^^^^^^
  File "/home/airflow/.local/lib/python3.12/site-packages/airflow/operators/python.py", line 256, in execute_callable
    return runner.run(*self.op_args, **self.op_kwargs)
           ^^^^^^^^^^^^^^^^^^^^^^^^^^^^^^^^^^^^^^^^^^^
  File "/home/airflow/.local/lib/python3.12/site-packages/airflow/utils/operator_helpers.py", line 252, in run
    return self.func(*args, **kwargs)
           ^^^^^^^^^^^^^^^^^^^^^^^^^^
  File "/opt/airflow/dags/test_car_5 _tg.py", line 144, in process_file
    currency_rate = get_currency_rate(execution_date)
                    ^^^^^^^^^^^^^^^^^^^^^^^^^^^^^^^^^
  File "/opt/airflow/dags/test_car_5 _tg.py", line 118, in get_currency_rate
    time.sleep(retry_delay)
  File "/home/airflow/.local/lib/python3.12/site-packages/airflow/models/taskinstance.py", line 3095, in signal_handler
    raise AirflowTaskTerminated("Task received SIGTERM signal")
airflow.exceptions.AirflowTaskTerminated: Task received SIGTERM signal
[2025-05-21T18:19:35.035+0000] {taskinstance.py:1225} INFO - Marking task as UP_FOR_RETRY. dag_id=test_car_5_tg, task_id=process_file, run_id=manual__2025-05-21T18:18:57.580086+00:00, execution_date=20250521T181857, start_date=20250521T181904, end_date=20250521T181935
[2025-05-21T18:19:35.061+0000] {taskinstance.py:340} INFO - ::group::Post task execution logs
[2025-05-21T18:19:35.063+0000] {standard_task_runner.py:124} ERROR - Failed to execute job 13 for task process_file ((psycopg2.errors.ForeignKeyViolation) insert or update on table "task_fail" violates foreign key constraint "task_fail_ti_fkey"
DETAIL:  Key (dag_id, task_id, run_id, map_index)=(test_car_5_tg, process_file, manual__2025-05-21T18:18:57.580086+00:00, -1) is not present in table "task_instance".

[SQL: INSERT INTO task_fail (task_id, dag_id, run_id, map_index, start_date, end_date, duration) VALUES (%(task_id)s, %(dag_id)s, %(run_id)s, %(map_index)s, %(start_date)s, %(end_date)s, %(duration)s) RETURNING task_fail.id]
[parameters: {'task_id': 'process_file', 'dag_id': 'test_car_5_tg', 'run_id': 'manual__2025-05-21T18:18:57.580086+00:00', 'map_index': -1, 'start_date': datetime.datetime(2025, 5, 21, 18, 19, 4, 394444, tzinfo=Timezone('UTC')), 'end_date': datetime.datetime(2025, 5, 21, 18, 19, 35, 34497, tzinfo=Timezone('UTC')), 'duration': 30}]
(Background on this error at: https://sqlalche.me/e/14/gkpj); 1031)
Traceback (most recent call last):
  File "/opt/airflow/dags/test_car_5 _tg.py", line 96, in get_currency_rate
    cursor.execute("""
psycopg2.errors.UndefinedTable: relation "cur_rate" does not exist
LINE 2:                             INSERT INTO cur_rate 
                                                ^


During handling of the above exception, another exception occurred:

Traceback (most recent call last):
  File "/home/airflow/.local/lib/python3.12/site-packages/airflow/models/taskinstance.py", line 273, in _run_raw_task
    TaskInstance._execute_task_with_callbacks(
  File "/home/airflow/.local/lib/python3.12/site-packages/airflow/models/taskinstance.py", line 3159, in _execute_task_with_callbacks
    result = self._execute_task(context, task_orig)
             ^^^^^^^^^^^^^^^^^^^^^^^^^^^^^^^^^^^^^^
  File "/home/airflow/.local/lib/python3.12/site-packages/airflow/models/taskinstance.py", line 3183, in _execute_task
    return _execute_task(self, context, task_orig)
           ^^^^^^^^^^^^^^^^^^^^^^^^^^^^^^^^^^^^^^^
  File "/home/airflow/.local/lib/python3.12/site-packages/airflow/models/taskinstance.py", line 767, in _execute_task
    result = _execute_callable(context=context, **execute_callable_kwargs)
             ^^^^^^^^^^^^^^^^^^^^^^^^^^^^^^^^^^^^^^^^^^^^^^^^^^^^^^^^^^^^^
  File "/home/airflow/.local/lib/python3.12/site-packages/airflow/models/taskinstance.py", line 733, in _execute_callable
    return ExecutionCallableRunner(
           ^^^^^^^^^^^^^^^^^^^^^^^^
  File "/home/airflow/.local/lib/python3.12/site-packages/airflow/utils/operator_helpers.py", line 252, in run
    return self.func(*args, **kwargs)
           ^^^^^^^^^^^^^^^^^^^^^^^^^^
  File "/home/airflow/.local/lib/python3.12/site-packages/airflow/models/baseoperator.py", line 422, in wrapper
    return func(self, *args, **kwargs)
           ^^^^^^^^^^^^^^^^^^^^^^^^^^^
  File "/home/airflow/.local/lib/python3.12/site-packages/airflow/operators/python.py", line 238, in execute
    return_value = self.execute_callable()
                   ^^^^^^^^^^^^^^^^^^^^^^^
  File "/home/airflow/.local/lib/python3.12/site-packages/airflow/operators/python.py", line 256, in execute_callable
    return runner.run(*self.op_args, **self.op_kwargs)
           ^^^^^^^^^^^^^^^^^^^^^^^^^^^^^^^^^^^^^^^^^^^
  File "/home/airflow/.local/lib/python3.12/site-packages/airflow/utils/operator_helpers.py", line 252, in run
    return self.func(*args, **kwargs)
           ^^^^^^^^^^^^^^^^^^^^^^^^^^
  File "/opt/airflow/dags/test_car_5 _tg.py", line 144, in process_file
    currency_rate = get_currency_rate(execution_date)
                    ^^^^^^^^^^^^^^^^^^^^^^^^^^^^^^^^^
  File "/opt/airflow/dags/test_car_5 _tg.py", line 118, in get_currency_rate
    time.sleep(retry_delay)
  File "/home/airflow/.local/lib/python3.12/site-packages/airflow/models/taskinstance.py", line 3095, in signal_handler
    raise AirflowTaskTerminated("Task received SIGTERM signal")
airflow.exceptions.AirflowTaskTerminated: Task received SIGTERM signal

During handling of the above exception, another exception occurred:

Traceback (most recent call last):
  File "/home/airflow/.local/lib/python3.12/site-packages/sqlalchemy/engine/base.py", line 1910, in _execute_context
    self.dialect.do_execute(
  File "/home/airflow/.local/lib/python3.12/site-packages/sqlalchemy/engine/default.py", line 736, in do_execute
    cursor.execute(statement, parameters)
psycopg2.errors.ForeignKeyViolation: insert or update on table "task_fail" violates foreign key constraint "task_fail_ti_fkey"
DETAIL:  Key (dag_id, task_id, run_id, map_index)=(test_car_5_tg, process_file, manual__2025-05-21T18:18:57.580086+00:00, -1) is not present in table "task_instance".


The above exception was the direct cause of the following exception:

Traceback (most recent call last):
  File "/home/airflow/.local/lib/python3.12/site-packages/airflow/task/task_runner/standard_task_runner.py", line 117, in _start_by_fork
    ret = args.func(args, dag=self.dag)
          ^^^^^^^^^^^^^^^^^^^^^^^^^^^^^
  File "/home/airflow/.local/lib/python3.12/site-packages/airflow/cli/cli_config.py", line 49, in command
    return func(*args, **kwargs)
           ^^^^^^^^^^^^^^^^^^^^^
  File "/home/airflow/.local/lib/python3.12/site-packages/airflow/utils/cli.py", line 116, in wrapper
    return f(*args, **kwargs)
           ^^^^^^^^^^^^^^^^^^
  File "/home/airflow/.local/lib/python3.12/site-packages/airflow/cli/commands/task_command.py", line 483, in task_run
    task_return_code = _run_task_by_selected_method(args, _dag, ti)
                       ^^^^^^^^^^^^^^^^^^^^^^^^^^^^^^^^^^^^^^^^^^^^
  File "/home/airflow/.local/lib/python3.12/site-packages/airflow/cli/commands/task_command.py", line 256, in _run_task_by_selected_method
    return _run_raw_task(args, ti)
           ^^^^^^^^^^^^^^^^^^^^^^^
  File "/home/airflow/.local/lib/python3.12/site-packages/airflow/cli/commands/task_command.py", line 341, in _run_raw_task
    return ti._run_raw_task(
           ^^^^^^^^^^^^^^^^^
  File "/home/airflow/.local/lib/python3.12/site-packages/airflow/utils/session.py", line 97, in wrapper
    return func(*args, session=session, **kwargs)
           ^^^^^^^^^^^^^^^^^^^^^^^^^^^^^^^^^^^^^^
  File "/home/airflow/.local/lib/python3.12/site-packages/airflow/models/taskinstance.py", line 3005, in _run_raw_task
    return _run_raw_task(
           ^^^^^^^^^^^^^^
  File "/home/airflow/.local/lib/python3.12/site-packages/airflow/models/taskinstance.py", line 327, in _run_raw_task
    ti.handle_failure(e, test_mode, context, session=session)
  File "/home/airflow/.local/lib/python3.12/site-packages/airflow/utils/session.py", line 94, in wrapper
    return func(*args, **kwargs)
           ^^^^^^^^^^^^^^^^^^^^^
  File "/home/airflow/.local/lib/python3.12/site-packages/airflow/models/taskinstance.py", line 3428, in handle_failure
    _handle_failure(
  File "/home/airflow/.local/lib/python3.12/site-packages/airflow/utils/session.py", line 94, in wrapper
    return func(*args, **kwargs)
           ^^^^^^^^^^^^^^^^^^^^^
  File "/home/airflow/.local/lib/python3.12/site-packages/airflow/api_internal/internal_api_call.py", line 166, in wrapper
    return func(*args, **kwargs)
           ^^^^^^^^^^^^^^^^^^^^^
  File "/home/airflow/.local/lib/python3.12/site-packages/airflow/models/taskinstance.py", line 1243, in _handle_failure
    TaskInstance.save_to_db(failure_context["ti"], session)
  File "/home/airflow/.local/lib/python3.12/site-packages/airflow/api_internal/internal_api_call.py", line 166, in wrapper
    return func(*args, **kwargs)
           ^^^^^^^^^^^^^^^^^^^^^
  File "/home/airflow/.local/lib/python3.12/site-packages/airflow/utils/session.py", line 94, in wrapper
    return func(*args, **kwargs)
           ^^^^^^^^^^^^^^^^^^^^^
  File "/home/airflow/.local/lib/python3.12/site-packages/airflow/models/taskinstance.py", line 3400, in save_to_db
    session.flush()
  File "/home/airflow/.local/lib/python3.12/site-packages/sqlalchemy/orm/session.py", line 3449, in flush
    self._flush(objects)
  File "/home/airflow/.local/lib/python3.12/site-packages/sqlalchemy/orm/session.py", line 3588, in _flush
    with util.safe_reraise():
         ^^^^^^^^^^^^^^^^^^^
  File "/home/airflow/.local/lib/python3.12/site-packages/sqlalchemy/util/langhelpers.py", line 70, in __exit__
    compat.raise_(
  File "/home/airflow/.local/lib/python3.12/site-packages/sqlalchemy/util/compat.py", line 211, in raise_
    raise exception
  File "/home/airflow/.local/lib/python3.12/site-packages/sqlalchemy/orm/session.py", line 3549, in _flush
    flush_context.execute()
  File "/home/airflow/.local/lib/python3.12/site-packages/sqlalchemy/orm/unitofwork.py", line 456, in execute
    rec.execute(self)
  File "/home/airflow/.local/lib/python3.12/site-packages/sqlalchemy/orm/unitofwork.py", line 630, in execute
    util.preloaded.orm_persistence.save_obj(
  File "/home/airflow/.local/lib/python3.12/site-packages/sqlalchemy/orm/persistence.py", line 245, in save_obj
    _emit_insert_statements(
  File "/home/airflow/.local/lib/python3.12/site-packages/sqlalchemy/orm/persistence.py", line 1238, in _emit_insert_statements
    result = connection._execute_20(
             ^^^^^^^^^^^^^^^^^^^^^^^
  File "/home/airflow/.local/lib/python3.12/site-packages/sqlalchemy/engine/base.py", line 1710, in _execute_20
    return meth(self, args_10style, kwargs_10style, execution_options)
           ^^^^^^^^^^^^^^^^^^^^^^^^^^^^^^^^^^^^^^^^^^^^^^^^^^^^^^^^^^^
  File "/home/airflow/.local/lib/python3.12/site-packages/sqlalchemy/sql/elements.py", line 334, in _execute_on_connection
    return connection._execute_clauseelement(
           ^^^^^^^^^^^^^^^^^^^^^^^^^^^^^^^^^^
  File "/home/airflow/.local/lib/python3.12/site-packages/sqlalchemy/engine/base.py", line 1577, in _execute_clauseelement
    ret = self._execute_context(
          ^^^^^^^^^^^^^^^^^^^^^^
  File "/home/airflow/.local/lib/python3.12/site-packages/sqlalchemy/engine/base.py", line 1953, in _execute_context
    self._handle_dbapi_exception(
  File "/home/airflow/.local/lib/python3.12/site-packages/sqlalchemy/engine/base.py", line 2134, in _handle_dbapi_exception
    util.raise_(
  File "/home/airflow/.local/lib/python3.12/site-packages/sqlalchemy/util/compat.py", line 211, in raise_
    raise exception
  File "/home/airflow/.local/lib/python3.12/site-packages/sqlalchemy/engine/base.py", line 1910, in _execute_context
    self.dialect.do_execute(
  File "/home/airflow/.local/lib/python3.12/site-packages/sqlalchemy/engine/default.py", line 736, in do_execute
    cursor.execute(statement, parameters)
sqlalchemy.exc.IntegrityError: (psycopg2.errors.ForeignKeyViolation) insert or update on table "task_fail" violates foreign key constraint "task_fail_ti_fkey"
DETAIL:  Key (dag_id, task_id, run_id, map_index)=(test_car_5_tg, process_file, manual__2025-05-21T18:18:57.580086+00:00, -1) is not present in table "task_instance".

[SQL: INSERT INTO task_fail (task_id, dag_id, run_id, map_index, start_date, end_date, duration) VALUES (%(task_id)s, %(dag_id)s, %(run_id)s, %(map_index)s, %(start_date)s, %(end_date)s, %(duration)s) RETURNING task_fail.id]
[parameters: {'task_id': 'process_file', 'dag_id': 'test_car_5_tg', 'run_id': 'manual__2025-05-21T18:18:57.580086+00:00', 'map_index': -1, 'start_date': datetime.datetime(2025, 5, 21, 18, 19, 4, 394444, tzinfo=Timezone('UTC')), 'end_date': datetime.datetime(2025, 5, 21, 18, 19, 35, 34497, tzinfo=Timezone('UTC')), 'duration': 30}]
(Background on this error at: https://sqlalche.me/e/14/gkpj)
[2025-05-21T18:19:35.135+0000] {process_utils.py:80} INFO - Process psutil.Process(pid=1031, status='terminated', exitcode=1, started='18:19:04') (1031) terminated with exit code 1
