[2025-05-22T11:02:21.947+0000] {local_task_job_runner.py:123} INFO - ::group::Pre task execution logs
[2025-05-22T11:02:21.974+0000] {taskinstance.py:2613} INFO - Dependencies all met for dep_context=non-requeueable deps ti=<TaskInstance: test_car_5_tg_err.process_file scheduled__2025-05-21T00:00:00+00:00 [queued]>
[2025-05-22T11:02:21.987+0000] {taskinstance.py:2613} INFO - Dependencies all met for dep_context=requeueable deps ti=<TaskInstance: test_car_5_tg_err.process_file scheduled__2025-05-21T00:00:00+00:00 [queued]>
[2025-05-22T11:02:21.988+0000] {taskinstance.py:2866} INFO - Starting attempt 1 of 2
[2025-05-22T11:02:22.007+0000] {taskinstance.py:2889} INFO - Executing <Task(PythonOperator): process_file> on 2025-05-21 00:00:00+00:00
[2025-05-22T11:02:22.019+0000] {warnings.py:112} WARNING - /home/***/.local/lib/python3.12/site-packages/***/task/task_runner/standard_task_runner.py:70: DeprecationWarning: This process (pid=344) is multi-threaded, use of fork() may lead to deadlocks in the child.
  pid = os.fork()

[2025-05-22T11:02:22.022+0000] {standard_task_runner.py:72} INFO - Started process 346 to run task
[2025-05-22T11:02:22.022+0000] {standard_task_runner.py:104} INFO - Running: ['***', 'tasks', 'run', 'test_car_5_tg_err', 'process_file', 'scheduled__2025-05-21T00:00:00+00:00', '--job-id', '8', '--raw', '--subdir', 'DAGS_FOLDER/test_car_5 _tg_err.py', '--cfg-path', '/tmp/tmpn3pwg1wg']
[2025-05-22T11:02:22.025+0000] {standard_task_runner.py:105} INFO - Job 8: Subtask process_file
[2025-05-22T11:02:22.095+0000] {task_command.py:467} INFO - Running <TaskInstance: test_car_5_tg_err.process_file scheduled__2025-05-21T00:00:00+00:00 [running]> on host 11f730283060
[2025-05-22T11:02:22.203+0000] {taskinstance.py:3132} INFO - Exporting env vars: AIRFLOW_CTX_DAG_OWNER='***' AIRFLOW_CTX_DAG_ID='test_car_5_tg_err' AIRFLOW_CTX_TASK_ID='process_file' AIRFLOW_CTX_EXECUTION_DATE='2025-05-21T00:00:00+00:00' AIRFLOW_CTX_TRY_NUMBER='1' AIRFLOW_CTX_DAG_RUN_ID='scheduled__2025-05-21T00:00:00+00:00'
[2025-05-22T11:02:22.204+0000] {taskinstance.py:731} INFO - ::endgroup::
[2025-05-22T11:02:22.221+0000] {test_car_5 _tg_err.py:167} INFO - >>> [START] process_file
[2025-05-22T11:02:22.222+0000] {test_car_5 _tg_err.py:170} INFO - Execution date: 2025-05-21 00:00:00+00:00
[2025-05-22T11:02:22.609+0000] {test_car_5 _tg_err.py:142} WARNING - Attempt 1 failed to get currency rates: HTTPSConnectionPool(host='www.cbrr.ru', port=443): Max retries exceeded with url: /scripts/XML_daily.asp?date_req=21/05/2025 (Caused by SSLError(SSLCertVerificationError(1, "[SSL: CERTIFICATE_VERIFY_FAILED] certificate verify failed: Hostname mismatch, certificate is not valid for 'www.cbrr.ru'. (_ssl.c:1000)")))
[2025-05-22T11:02:37.917+0000] {test_car_5 _tg_err.py:142} WARNING - Attempt 2 failed to get currency rates: HTTPSConnectionPool(host='www.cbrr.ru', port=443): Max retries exceeded with url: /scripts/XML_daily.asp?date_req=21/05/2025 (Caused by SSLError(SSLCertVerificationError(1, "[SSL: CERTIFICATE_VERIFY_FAILED] certificate verify failed: Hostname mismatch, certificate is not valid for 'www.cbrr.ru'. (_ssl.c:1000)")))
[2025-05-22T11:02:53.283+0000] {test_car_5 _tg_err.py:142} WARNING - Attempt 3 failed to get currency rates: HTTPSConnectionPool(host='www.cbrr.ru', port=443): Max retries exceeded with url: /scripts/XML_daily.asp?date_req=21/05/2025 (Caused by SSLError(SSLCertVerificationError(1, "[SSL: CERTIFICATE_VERIFY_FAILED] certificate verify failed: Hostname mismatch, certificate is not valid for 'www.cbrr.ru'. (_ssl.c:1000)")))
[2025-05-22T11:02:53.877+0000] {test_car_5 _tg_err.py:59} INFO - Telegram notification sent successfully
[2025-05-22T11:02:53.878+0000] {test_car_5 _tg_err.py:158} ERROR - ⚠️ <b>Ошибка в DAG test_car_5_tg</b>
Не удалось получить курсы валют после 3 попыток
Последняя ошибка: HTTPSConnectionPool(host='www.cbrr.ru', port=443): Max retries exceeded with url: /scripts/XML_daily.asp?date_req=21/05/2025 (Caused by SSLError(SSLCertVerificationError(1, "[SSL: CERTIFICATE_VERIFY_FAILED] certificate verify failed: Hostname mismatch, certificate is not valid for 'www.cbrr.ru'. (_ssl.c:1000)")))
Дата выполнения: 2025-05-21 00:00:00+00:00
[2025-05-22T11:02:54.291+0000] {test_car_5 _tg_err.py:59} INFO - Telegram notification sent successfully
[2025-05-22T11:02:54.293+0000] {test_car_5 _tg_err.py:223} ERROR - Error in process_file: ⚠️ <b>Ошибка в DAG test_car_5_tg</b>
Не удалось получить курсы валют после 3 попыток
Последняя ошибка: HTTPSConnectionPool(host='www.cbrr.ru', port=443): Max retries exceeded with url: /scripts/XML_daily.asp?date_req=21/05/2025 (Caused by SSLError(SSLCertVerificationError(1, "[SSL: CERTIFICATE_VERIFY_FAILED] certificate verify failed: Hostname mismatch, certificate is not valid for 'www.cbrr.ru'. (_ssl.c:1000)")))
Дата выполнения: 2025-05-21 00:00:00+00:00
Traceback (most recent call last):
  File "/opt/airflow/dags/test_car_5 _tg_err.py", line 173, in process_file
    currency_rate = get_currency_rate(execution_date)
                    ^^^^^^^^^^^^^^^^^^^^^^^^^^^^^^^^^
  File "/opt/airflow/dags/test_car_5 _tg_err.py", line 159, in get_currency_rate
    raise Exception(error_message)
Exception: ⚠️ <b>Ошибка в DAG test_car_5_tg</b>
Не удалось получить курсы валют после 3 попыток
Последняя ошибка: HTTPSConnectionPool(host='www.cbrr.ru', port=443): Max retries exceeded with url: /scripts/XML_daily.asp?date_req=21/05/2025 (Caused by SSLError(SSLCertVerificationError(1, "[SSL: CERTIFICATE_VERIFY_FAILED] certificate verify failed: Hostname mismatch, certificate is not valid for 'www.cbrr.ru'. (_ssl.c:1000)")))
Дата выполнения: 2025-05-21 00:00:00+00:00
[2025-05-22T11:02:54.320+0000] {taskinstance.py:3311} ERROR - Task failed with exception
Traceback (most recent call last):
  File "/home/airflow/.local/lib/python3.12/site-packages/airflow/models/taskinstance.py", line 767, in _execute_task
    result = _execute_callable(context=context, **execute_callable_kwargs)
             ^^^^^^^^^^^^^^^^^^^^^^^^^^^^^^^^^^^^^^^^^^^^^^^^^^^^^^^^^^^^^
  File "/home/airflow/.local/lib/python3.12/site-packages/airflow/models/taskinstance.py", line 733, in _execute_callable
    return ExecutionCallableRunner(
           ^^^^^^^^^^^^^^^^^^^^^^^^
  File "/home/airflow/.local/lib/python3.12/site-packages/airflow/utils/operator_helpers.py", line 252, in run
    return self.func(*args, **kwargs)
           ^^^^^^^^^^^^^^^^^^^^^^^^^^
  File "/home/airflow/.local/lib/python3.12/site-packages/airflow/models/baseoperator.py", line 422, in wrapper
    return func(self, *args, **kwargs)
           ^^^^^^^^^^^^^^^^^^^^^^^^^^^
  File "/home/airflow/.local/lib/python3.12/site-packages/airflow/operators/python.py", line 238, in execute
    return_value = self.execute_callable()
                   ^^^^^^^^^^^^^^^^^^^^^^^
  File "/home/airflow/.local/lib/python3.12/site-packages/airflow/operators/python.py", line 256, in execute_callable
    return runner.run(*self.op_args, **self.op_kwargs)
           ^^^^^^^^^^^^^^^^^^^^^^^^^^^^^^^^^^^^^^^^^^^
  File "/home/airflow/.local/lib/python3.12/site-packages/airflow/utils/operator_helpers.py", line 252, in run
    return self.func(*args, **kwargs)
           ^^^^^^^^^^^^^^^^^^^^^^^^^^
  File "/opt/airflow/dags/test_car_5 _tg_err.py", line 173, in process_file
    currency_rate = get_currency_rate(execution_date)
                    ^^^^^^^^^^^^^^^^^^^^^^^^^^^^^^^^^
  File "/opt/airflow/dags/test_car_5 _tg_err.py", line 159, in get_currency_rate
    raise Exception(error_message)
Exception: ⚠️ <b>Ошибка в DAG test_car_5_tg</b>
Не удалось получить курсы валют после 3 попыток
Последняя ошибка: HTTPSConnectionPool(host='www.cbrr.ru', port=443): Max retries exceeded with url: /scripts/XML_daily.asp?date_req=21/05/2025 (Caused by SSLError(SSLCertVerificationError(1, "[SSL: CERTIFICATE_VERIFY_FAILED] certificate verify failed: Hostname mismatch, certificate is not valid for 'www.cbrr.ru'. (_ssl.c:1000)")))
Дата выполнения: 2025-05-21 00:00:00+00:00
[2025-05-22T11:02:54.375+0000] {taskinstance.py:1225} INFO - Marking task as UP_FOR_RETRY. dag_id=test_car_5_tg_err, task_id=process_file, run_id=scheduled__2025-05-21T00:00:00+00:00, execution_date=20250521T000000, start_date=20250522T110221, end_date=20250522T110254
[2025-05-22T11:02:54.428+0000] {taskinstance.py:340} INFO - ::group::Post task execution logs
[2025-05-22T11:02:54.429+0000] {standard_task_runner.py:124} ERROR - Failed to execute job 8 for task process_file (⚠️ <b>Ошибка в DAG test_car_5_tg</b>
Не удалось получить курсы валют после 3 попыток
Последняя ошибка: HTTPSConnectionPool(host='www.cbrr.ru', port=443): Max retries exceeded with url: /scripts/XML_daily.asp?date_req=21/05/2025 (Caused by SSLError(SSLCertVerificationError(1, "[SSL: CERTIFICATE_VERIFY_FAILED] certificate verify failed: Hostname mismatch, certificate is not valid for 'www.cbrr.ru'. (_ssl.c:1000)")))
Дата выполнения: 2025-05-21 00:00:00+00:00; 346)
Traceback (most recent call last):
  File "/home/airflow/.local/lib/python3.12/site-packages/airflow/task/task_runner/standard_task_runner.py", line 117, in _start_by_fork
    ret = args.func(args, dag=self.dag)
          ^^^^^^^^^^^^^^^^^^^^^^^^^^^^^
  File "/home/airflow/.local/lib/python3.12/site-packages/airflow/cli/cli_config.py", line 49, in command
    return func(*args, **kwargs)
           ^^^^^^^^^^^^^^^^^^^^^
  File "/home/airflow/.local/lib/python3.12/site-packages/airflow/utils/cli.py", line 116, in wrapper
    return f(*args, **kwargs)
           ^^^^^^^^^^^^^^^^^^
  File "/home/airflow/.local/lib/python3.12/site-packages/airflow/cli/commands/task_command.py", line 483, in task_run
    task_return_code = _run_task_by_selected_method(args, _dag, ti)
                       ^^^^^^^^^^^^^^^^^^^^^^^^^^^^^^^^^^^^^^^^^^^^
  File "/home/airflow/.local/lib/python3.12/site-packages/airflow/cli/commands/task_command.py", line 256, in _run_task_by_selected_method
    return _run_raw_task(args, ti)
           ^^^^^^^^^^^^^^^^^^^^^^^
  File "/home/airflow/.local/lib/python3.12/site-packages/airflow/cli/commands/task_command.py", line 341, in _run_raw_task
    return ti._run_raw_task(
           ^^^^^^^^^^^^^^^^^
  File "/home/airflow/.local/lib/python3.12/site-packages/airflow/utils/session.py", line 97, in wrapper
    return func(*args, session=session, **kwargs)
           ^^^^^^^^^^^^^^^^^^^^^^^^^^^^^^^^^^^^^^
  File "/home/airflow/.local/lib/python3.12/site-packages/airflow/models/taskinstance.py", line 3005, in _run_raw_task
    return _run_raw_task(
           ^^^^^^^^^^^^^^
  File "/home/airflow/.local/lib/python3.12/site-packages/airflow/models/taskinstance.py", line 273, in _run_raw_task
    TaskInstance._execute_task_with_callbacks(
  File "/home/airflow/.local/lib/python3.12/site-packages/airflow/models/taskinstance.py", line 3159, in _execute_task_with_callbacks
    result = self._execute_task(context, task_orig)
             ^^^^^^^^^^^^^^^^^^^^^^^^^^^^^^^^^^^^^^
  File "/home/airflow/.local/lib/python3.12/site-packages/airflow/models/taskinstance.py", line 3183, in _execute_task
    return _execute_task(self, context, task_orig)
           ^^^^^^^^^^^^^^^^^^^^^^^^^^^^^^^^^^^^^^^
  File "/home/airflow/.local/lib/python3.12/site-packages/airflow/models/taskinstance.py", line 767, in _execute_task
    result = _execute_callable(context=context, **execute_callable_kwargs)
             ^^^^^^^^^^^^^^^^^^^^^^^^^^^^^^^^^^^^^^^^^^^^^^^^^^^^^^^^^^^^^
  File "/home/airflow/.local/lib/python3.12/site-packages/airflow/models/taskinstance.py", line 733, in _execute_callable
    return ExecutionCallableRunner(
           ^^^^^^^^^^^^^^^^^^^^^^^^
  File "/home/airflow/.local/lib/python3.12/site-packages/airflow/utils/operator_helpers.py", line 252, in run
    return self.func(*args, **kwargs)
           ^^^^^^^^^^^^^^^^^^^^^^^^^^
  File "/home/airflow/.local/lib/python3.12/site-packages/airflow/models/baseoperator.py", line 422, in wrapper
    return func(self, *args, **kwargs)
           ^^^^^^^^^^^^^^^^^^^^^^^^^^^
  File "/home/airflow/.local/lib/python3.12/site-packages/airflow/operators/python.py", line 238, in execute
    return_value = self.execute_callable()
                   ^^^^^^^^^^^^^^^^^^^^^^^
  File "/home/airflow/.local/lib/python3.12/site-packages/airflow/operators/python.py", line 256, in execute_callable
    return runner.run(*self.op_args, **self.op_kwargs)
           ^^^^^^^^^^^^^^^^^^^^^^^^^^^^^^^^^^^^^^^^^^^
  File "/home/airflow/.local/lib/python3.12/site-packages/airflow/utils/operator_helpers.py", line 252, in run
    return self.func(*args, **kwargs)
           ^^^^^^^^^^^^^^^^^^^^^^^^^^
  File "/opt/airflow/dags/test_car_5 _tg_err.py", line 173, in process_file
    currency_rate = get_currency_rate(execution_date)
                    ^^^^^^^^^^^^^^^^^^^^^^^^^^^^^^^^^
  File "/opt/airflow/dags/test_car_5 _tg_err.py", line 159, in get_currency_rate
    raise Exception(error_message)
Exception: ⚠️ <b>Ошибка в DAG test_car_5_tg</b>
Не удалось получить курсы валют после 3 попыток
Последняя ошибка: HTTPSConnectionPool(host='www.cbrr.ru', port=443): Max retries exceeded with url: /scripts/XML_daily.asp?date_req=21/05/2025 (Caused by SSLError(SSLCertVerificationError(1, "[SSL: CERTIFICATE_VERIFY_FAILED] certificate verify failed: Hostname mismatch, certificate is not valid for 'www.cbrr.ru'. (_ssl.c:1000)")))
Дата выполнения: 2025-05-21 00:00:00+00:00
[2025-05-22T11:02:54.469+0000] {local_task_job_runner.py:266} INFO - Task exited with return code 1
[2025-05-22T11:02:54.501+0000] {taskinstance.py:3895} INFO - 0 downstream tasks scheduled from follow-on schedule check
[2025-05-22T11:02:54.505+0000] {local_task_job_runner.py:245} INFO - ::endgroup::
[2025-05-22T13:41:14.653+0000] {local_task_job_runner.py:123} INFO - ::group::Pre task execution logs
[2025-05-22T13:41:14.761+0000] {taskinstance.py:2613} INFO - Dependencies all met for dep_context=non-requeueable deps ti=<TaskInstance: test_car_5_tg_err.process_file scheduled__2025-05-21T00:00:00+00:00 [queued]>
[2025-05-22T13:41:14.795+0000] {taskinstance.py:2613} INFO - Dependencies all met for dep_context=requeueable deps ti=<TaskInstance: test_car_5_tg_err.process_file scheduled__2025-05-21T00:00:00+00:00 [queued]>
[2025-05-22T13:41:14.803+0000] {taskinstance.py:2866} INFO - Starting attempt 1 of 2
[2025-05-22T13:41:14.875+0000] {taskinstance.py:2889} INFO - Executing <Task(PythonOperator): process_file> on 2025-05-21 00:00:00+00:00
[2025-05-22T13:41:14.913+0000] {warnings.py:112} WARNING - /home/***/.local/lib/python3.12/site-packages/***/task/task_runner/standard_task_runner.py:70: DeprecationWarning: This process (pid=239) is multi-threaded, use of fork() may lead to deadlocks in the child.
  pid = os.fork()

[2025-05-22T13:41:14.924+0000] {standard_task_runner.py:72} INFO - Started process 248 to run task
[2025-05-22T13:41:14.921+0000] {standard_task_runner.py:104} INFO - Running: ['***', 'tasks', 'run', 'test_car_5_tg_err', 'process_file', 'scheduled__2025-05-21T00:00:00+00:00', '--job-id', '9', '--raw', '--subdir', 'DAGS_FOLDER/test_car_5 _tg_err.py', '--cfg-path', '/tmp/tmp53hnzt9m']
[2025-05-22T13:41:14.930+0000] {standard_task_runner.py:105} INFO - Job 9: Subtask process_file
[2025-05-22T13:41:15.141+0000] {task_command.py:467} INFO - Running <TaskInstance: test_car_5_tg_err.process_file scheduled__2025-05-21T00:00:00+00:00 [running]> on host 3d98b42a4b31
[2025-05-22T13:41:15.728+0000] {taskinstance.py:3132} INFO - Exporting env vars: AIRFLOW_CTX_DAG_OWNER='***' AIRFLOW_CTX_DAG_ID='test_car_5_tg_err' AIRFLOW_CTX_TASK_ID='process_file' AIRFLOW_CTX_EXECUTION_DATE='2025-05-21T00:00:00+00:00' AIRFLOW_CTX_TRY_NUMBER='1' AIRFLOW_CTX_DAG_RUN_ID='scheduled__2025-05-21T00:00:00+00:00'
[2025-05-22T13:41:15.736+0000] {taskinstance.py:731} INFO - ::endgroup::
[2025-05-22T13:41:15.870+0000] {test_car_5 _tg_err.py:167} INFO - >>> [START] process_file
[2025-05-22T13:41:15.896+0000] {test_car_5 _tg_err.py:170} INFO - Execution date: 2025-05-21 00:00:00+00:00
[2025-05-22T13:41:16.397+0000] {test_car_5 _tg_err.py:142} WARNING - Attempt 1 failed to get currency rates: HTTPSConnectionPool(host='www.cbrr.ru', port=443): Max retries exceeded with url: /scripts/XML_daily.asp?date_req=21/05/2025 (Caused by SSLError(SSLCertVerificationError(1, "[SSL: CERTIFICATE_VERIFY_FAILED] certificate verify failed: Hostname mismatch, certificate is not valid for 'www.cbrr.ru'. (_ssl.c:1000)")))
[2025-05-22T13:41:31.789+0000] {test_car_5 _tg_err.py:142} WARNING - Attempt 2 failed to get currency rates: HTTPSConnectionPool(host='www.cbrr.ru', port=443): Max retries exceeded with url: /scripts/XML_daily.asp?date_req=21/05/2025 (Caused by SSLError(SSLCertVerificationError(1, "[SSL: CERTIFICATE_VERIFY_FAILED] certificate verify failed: Hostname mismatch, certificate is not valid for 'www.cbrr.ru'. (_ssl.c:1000)")))
[2025-05-22T13:41:47.097+0000] {test_car_5 _tg_err.py:142} WARNING - Attempt 3 failed to get currency rates: HTTPSConnectionPool(host='www.cbrr.ru', port=443): Max retries exceeded with url: /scripts/XML_daily.asp?date_req=21/05/2025 (Caused by SSLError(SSLCertVerificationError(1, "[SSL: CERTIFICATE_VERIFY_FAILED] certificate verify failed: Hostname mismatch, certificate is not valid for 'www.cbrr.ru'. (_ssl.c:1000)")))
[2025-05-22T13:41:47.705+0000] {test_car_5 _tg_err.py:59} INFO - Telegram notification sent successfully
[2025-05-22T13:41:47.708+0000] {test_car_5 _tg_err.py:158} ERROR - ⚠️ <b>Ошибка в DAG test_car_5_tg_err</b>
Не удалось получить курсы валют после 3 попыток
Последняя ошибка: HTTPSConnectionPool(host='www.cbrr.ru', port=443): Max retries exceeded with url: /scripts/XML_daily.asp?date_req=21/05/2025 (Caused by SSLError(SSLCertVerificationError(1, "[SSL: CERTIFICATE_VERIFY_FAILED] certificate verify failed: Hostname mismatch, certificate is not valid for 'www.cbrr.ru'. (_ssl.c:1000)")))
Дата выполнения: 2025-05-21 00:00:00+00:00
[2025-05-22T13:41:48.163+0000] {test_car_5 _tg_err.py:59} INFO - Telegram notification sent successfully
[2025-05-22T13:41:48.166+0000] {test_car_5 _tg_err.py:223} ERROR - Error in process_file: ⚠️ <b>Ошибка в DAG test_car_5_tg_err</b>
Не удалось получить курсы валют после 3 попыток
Последняя ошибка: HTTPSConnectionPool(host='www.cbrr.ru', port=443): Max retries exceeded with url: /scripts/XML_daily.asp?date_req=21/05/2025 (Caused by SSLError(SSLCertVerificationError(1, "[SSL: CERTIFICATE_VERIFY_FAILED] certificate verify failed: Hostname mismatch, certificate is not valid for 'www.cbrr.ru'. (_ssl.c:1000)")))
Дата выполнения: 2025-05-21 00:00:00+00:00
Traceback (most recent call last):
  File "/opt/airflow/dags/test_car_5 _tg_err.py", line 173, in process_file
    currency_rate = get_currency_rate(execution_date)
                    ^^^^^^^^^^^^^^^^^^^^^^^^^^^^^^^^^
  File "/opt/airflow/dags/test_car_5 _tg_err.py", line 159, in get_currency_rate
    raise Exception(error_message)
Exception: ⚠️ <b>Ошибка в DAG test_car_5_tg_err</b>
Не удалось получить курсы валют после 3 попыток
Последняя ошибка: HTTPSConnectionPool(host='www.cbrr.ru', port=443): Max retries exceeded with url: /scripts/XML_daily.asp?date_req=21/05/2025 (Caused by SSLError(SSLCertVerificationError(1, "[SSL: CERTIFICATE_VERIFY_FAILED] certificate verify failed: Hostname mismatch, certificate is not valid for 'www.cbrr.ru'. (_ssl.c:1000)")))
Дата выполнения: 2025-05-21 00:00:00+00:00
[2025-05-22T13:41:48.185+0000] {taskinstance.py:3311} ERROR - Task failed with exception
Traceback (most recent call last):
  File "/home/airflow/.local/lib/python3.12/site-packages/airflow/models/taskinstance.py", line 767, in _execute_task
    result = _execute_callable(context=context, **execute_callable_kwargs)
             ^^^^^^^^^^^^^^^^^^^^^^^^^^^^^^^^^^^^^^^^^^^^^^^^^^^^^^^^^^^^^
  File "/home/airflow/.local/lib/python3.12/site-packages/airflow/models/taskinstance.py", line 733, in _execute_callable
    return ExecutionCallableRunner(
           ^^^^^^^^^^^^^^^^^^^^^^^^
  File "/home/airflow/.local/lib/python3.12/site-packages/airflow/utils/operator_helpers.py", line 252, in run
    return self.func(*args, **kwargs)
           ^^^^^^^^^^^^^^^^^^^^^^^^^^
  File "/home/airflow/.local/lib/python3.12/site-packages/airflow/models/baseoperator.py", line 422, in wrapper
    return func(self, *args, **kwargs)
           ^^^^^^^^^^^^^^^^^^^^^^^^^^^
  File "/home/airflow/.local/lib/python3.12/site-packages/airflow/operators/python.py", line 238, in execute
    return_value = self.execute_callable()
                   ^^^^^^^^^^^^^^^^^^^^^^^
  File "/home/airflow/.local/lib/python3.12/site-packages/airflow/operators/python.py", line 256, in execute_callable
    return runner.run(*self.op_args, **self.op_kwargs)
           ^^^^^^^^^^^^^^^^^^^^^^^^^^^^^^^^^^^^^^^^^^^
  File "/home/airflow/.local/lib/python3.12/site-packages/airflow/utils/operator_helpers.py", line 252, in run
    return self.func(*args, **kwargs)
           ^^^^^^^^^^^^^^^^^^^^^^^^^^
  File "/opt/airflow/dags/test_car_5 _tg_err.py", line 173, in process_file
    currency_rate = get_currency_rate(execution_date)
                    ^^^^^^^^^^^^^^^^^^^^^^^^^^^^^^^^^
  File "/opt/airflow/dags/test_car_5 _tg_err.py", line 159, in get_currency_rate
    raise Exception(error_message)
Exception: ⚠️ <b>Ошибка в DAG test_car_5_tg_err</b>
Не удалось получить курсы валют после 3 попыток
Последняя ошибка: HTTPSConnectionPool(host='www.cbrr.ru', port=443): Max retries exceeded with url: /scripts/XML_daily.asp?date_req=21/05/2025 (Caused by SSLError(SSLCertVerificationError(1, "[SSL: CERTIFICATE_VERIFY_FAILED] certificate verify failed: Hostname mismatch, certificate is not valid for 'www.cbrr.ru'. (_ssl.c:1000)")))
Дата выполнения: 2025-05-21 00:00:00+00:00
[2025-05-22T13:41:48.257+0000] {taskinstance.py:1225} INFO - Marking task as UP_FOR_RETRY. dag_id=test_car_5_tg_err, task_id=process_file, run_id=scheduled__2025-05-21T00:00:00+00:00, execution_date=20250521T000000, start_date=20250522T134114, end_date=20250522T134148
[2025-05-22T13:41:48.376+0000] {taskinstance.py:340} INFO - ::group::Post task execution logs
[2025-05-22T13:41:48.379+0000] {standard_task_runner.py:124} ERROR - Failed to execute job 9 for task process_file (⚠️ <b>Ошибка в DAG test_car_5_tg_err</b>
Не удалось получить курсы валют после 3 попыток
Последняя ошибка: HTTPSConnectionPool(host='www.cbrr.ru', port=443): Max retries exceeded with url: /scripts/XML_daily.asp?date_req=21/05/2025 (Caused by SSLError(SSLCertVerificationError(1, "[SSL: CERTIFICATE_VERIFY_FAILED] certificate verify failed: Hostname mismatch, certificate is not valid for 'www.cbrr.ru'. (_ssl.c:1000)")))
Дата выполнения: 2025-05-21 00:00:00+00:00; 248)
Traceback (most recent call last):
  File "/home/airflow/.local/lib/python3.12/site-packages/airflow/task/task_runner/standard_task_runner.py", line 117, in _start_by_fork
    ret = args.func(args, dag=self.dag)
          ^^^^^^^^^^^^^^^^^^^^^^^^^^^^^
  File "/home/airflow/.local/lib/python3.12/site-packages/airflow/cli/cli_config.py", line 49, in command
    return func(*args, **kwargs)
           ^^^^^^^^^^^^^^^^^^^^^
  File "/home/airflow/.local/lib/python3.12/site-packages/airflow/utils/cli.py", line 116, in wrapper
    return f(*args, **kwargs)
           ^^^^^^^^^^^^^^^^^^
  File "/home/airflow/.local/lib/python3.12/site-packages/airflow/cli/commands/task_command.py", line 483, in task_run
    task_return_code = _run_task_by_selected_method(args, _dag, ti)
                       ^^^^^^^^^^^^^^^^^^^^^^^^^^^^^^^^^^^^^^^^^^^^
  File "/home/airflow/.local/lib/python3.12/site-packages/airflow/cli/commands/task_command.py", line 256, in _run_task_by_selected_method
    return _run_raw_task(args, ti)
           ^^^^^^^^^^^^^^^^^^^^^^^
  File "/home/airflow/.local/lib/python3.12/site-packages/airflow/cli/commands/task_command.py", line 341, in _run_raw_task
    return ti._run_raw_task(
           ^^^^^^^^^^^^^^^^^
  File "/home/airflow/.local/lib/python3.12/site-packages/airflow/utils/session.py", line 97, in wrapper
    return func(*args, session=session, **kwargs)
           ^^^^^^^^^^^^^^^^^^^^^^^^^^^^^^^^^^^^^^
  File "/home/airflow/.local/lib/python3.12/site-packages/airflow/models/taskinstance.py", line 3005, in _run_raw_task
    return _run_raw_task(
           ^^^^^^^^^^^^^^
  File "/home/airflow/.local/lib/python3.12/site-packages/airflow/models/taskinstance.py", line 273, in _run_raw_task
    TaskInstance._execute_task_with_callbacks(
  File "/home/airflow/.local/lib/python3.12/site-packages/airflow/models/taskinstance.py", line 3159, in _execute_task_with_callbacks
    result = self._execute_task(context, task_orig)
             ^^^^^^^^^^^^^^^^^^^^^^^^^^^^^^^^^^^^^^
  File "/home/airflow/.local/lib/python3.12/site-packages/airflow/models/taskinstance.py", line 3183, in _execute_task
    return _execute_task(self, context, task_orig)
           ^^^^^^^^^^^^^^^^^^^^^^^^^^^^^^^^^^^^^^^
  File "/home/airflow/.local/lib/python3.12/site-packages/airflow/models/taskinstance.py", line 767, in _execute_task
    result = _execute_callable(context=context, **execute_callable_kwargs)
             ^^^^^^^^^^^^^^^^^^^^^^^^^^^^^^^^^^^^^^^^^^^^^^^^^^^^^^^^^^^^^
  File "/home/airflow/.local/lib/python3.12/site-packages/airflow/models/taskinstance.py", line 733, in _execute_callable
    return ExecutionCallableRunner(
           ^^^^^^^^^^^^^^^^^^^^^^^^
  File "/home/airflow/.local/lib/python3.12/site-packages/airflow/utils/operator_helpers.py", line 252, in run
    return self.func(*args, **kwargs)
           ^^^^^^^^^^^^^^^^^^^^^^^^^^
  File "/home/airflow/.local/lib/python3.12/site-packages/airflow/models/baseoperator.py", line 422, in wrapper
    return func(self, *args, **kwargs)
           ^^^^^^^^^^^^^^^^^^^^^^^^^^^
  File "/home/airflow/.local/lib/python3.12/site-packages/airflow/operators/python.py", line 238, in execute
    return_value = self.execute_callable()
                   ^^^^^^^^^^^^^^^^^^^^^^^
  File "/home/airflow/.local/lib/python3.12/site-packages/airflow/operators/python.py", line 256, in execute_callable
    return runner.run(*self.op_args, **self.op_kwargs)
           ^^^^^^^^^^^^^^^^^^^^^^^^^^^^^^^^^^^^^^^^^^^
  File "/home/airflow/.local/lib/python3.12/site-packages/airflow/utils/operator_helpers.py", line 252, in run
    return self.func(*args, **kwargs)
           ^^^^^^^^^^^^^^^^^^^^^^^^^^
  File "/opt/airflow/dags/test_car_5 _tg_err.py", line 173, in process_file
    currency_rate = get_currency_rate(execution_date)
                    ^^^^^^^^^^^^^^^^^^^^^^^^^^^^^^^^^
  File "/opt/airflow/dags/test_car_5 _tg_err.py", line 159, in get_currency_rate
    raise Exception(error_message)
Exception: ⚠️ <b>Ошибка в DAG test_car_5_tg_err</b>
Не удалось получить курсы валют после 3 попыток
Последняя ошибка: HTTPSConnectionPool(host='www.cbrr.ru', port=443): Max retries exceeded with url: /scripts/XML_daily.asp?date_req=21/05/2025 (Caused by SSLError(SSLCertVerificationError(1, "[SSL: CERTIFICATE_VERIFY_FAILED] certificate verify failed: Hostname mismatch, certificate is not valid for 'www.cbrr.ru'. (_ssl.c:1000)")))
Дата выполнения: 2025-05-21 00:00:00+00:00
[2025-05-22T13:41:48.451+0000] {local_task_job_runner.py:266} INFO - Task exited with return code 1
[2025-05-22T13:41:48.549+0000] {taskinstance.py:3895} INFO - 0 downstream tasks scheduled from follow-on schedule check
[2025-05-22T13:41:48.555+0000] {local_task_job_runner.py:245} INFO - ::endgroup::
