[2025-05-22T10:55:20.285+0000] {local_task_job_runner.py:123} INFO - ::group::Pre task execution logs
[2025-05-22T10:55:20.359+0000] {taskinstance.py:2613} INFO - Dependencies all met for dep_context=non-requeueable deps ti=<TaskInstance: test_car_5_tg.process_file manual__2025-05-22T10:54:53.856104+00:00 [queued]>
[2025-05-22T10:55:20.387+0000] {taskinstance.py:2613} INFO - Dependencies all met for dep_context=requeueable deps ti=<TaskInstance: test_car_5_tg.process_file manual__2025-05-22T10:54:53.856104+00:00 [queued]>
[2025-05-22T10:55:20.389+0000] {taskinstance.py:2866} INFO - Starting attempt 1 of 2
[2025-05-22T10:55:20.423+0000] {taskinstance.py:2889} INFO - Executing <Task(PythonOperator): process_file> on 2025-05-22 10:54:53.856104+00:00
[2025-05-22T10:55:20.452+0000] {warnings.py:112} WARNING - /home/***/.local/lib/python3.12/site-packages/***/task/task_runner/standard_task_runner.py:70: DeprecationWarning: This process (pid=245) is multi-threaded, use of fork() may lead to deadlocks in the child.
  pid = os.fork()

[2025-05-22T10:55:20.460+0000] {standard_task_runner.py:72} INFO - Started process 254 to run task
[2025-05-22T10:55:20.462+0000] {standard_task_runner.py:104} INFO - Running: ['***', 'tasks', 'run', 'test_car_5_tg', 'process_file', 'manual__2025-05-22T10:54:53.856104+00:00', '--job-id', '5', '--raw', '--subdir', 'DAGS_FOLDER/test_car_5 _tg.py', '--cfg-path', '/tmp/tmpvlo0nv5f']
[2025-05-22T10:55:20.469+0000] {standard_task_runner.py:105} INFO - Job 5: Subtask process_file
[2025-05-22T10:55:20.643+0000] {task_command.py:467} INFO - Running <TaskInstance: test_car_5_tg.process_file manual__2025-05-22T10:54:53.856104+00:00 [running]> on host 11f730283060
[2025-05-22T10:55:21.104+0000] {taskinstance.py:3132} INFO - Exporting env vars: AIRFLOW_CTX_DAG_OWNER='***' AIRFLOW_CTX_DAG_ID='test_car_5_tg' AIRFLOW_CTX_TASK_ID='process_file' AIRFLOW_CTX_EXECUTION_DATE='2025-05-22T10:54:53.856104+00:00' AIRFLOW_CTX_TRY_NUMBER='1' AIRFLOW_CTX_DAG_RUN_ID='manual__2025-05-22T10:54:53.856104+00:00'
[2025-05-22T10:55:21.106+0000] {taskinstance.py:731} INFO - ::endgroup::
[2025-05-22T10:55:21.143+0000] {test_car_5 _tg.py:167} INFO - >>> [START] process_file
[2025-05-22T10:55:21.144+0000] {test_car_5 _tg.py:170} INFO - Execution date: 2025-05-22 10:54:53.856104+00:00
[2025-05-22T10:55:24.194+0000] {base.py:84} INFO - Retrieving connection 'postgres_default'
[2025-05-22T10:55:24.362+0000] {test_car_5 _tg.py:174} INFO - Currency rate: 26.5525
[2025-05-22T10:55:24.478+0000] {base.py:84} INFO - Retrieving connection 'minio_conn'
[2025-05-22T10:55:24.496+0000] {connection_wrapper.py:328} INFO - AWS Connection (conn_id='minio_conn', conn_type='aws') credentials retrieved from extra.
[2025-05-22T10:55:26.953+0000] {test_car_5 _tg.py:59} INFO - Telegram notification sent successfully
[2025-05-22T10:55:27.486+0000] {test_car_5 _tg.py:59} INFO - Telegram notification sent successfully
[2025-05-22T10:55:27.490+0000] {test_car_5 _tg.py:223} ERROR - Error in process_file: Файл cars_20250522.csv не найден в бакете car-prices-bucket
Traceback (most recent call last):
  File "/opt/airflow/dags/test_car_5 _tg.py", line 188, in process_file
    raise ValueError(error_msg)
ValueError: Файл cars_20250522.csv не найден в бакете car-prices-bucket
[2025-05-22T10:55:27.506+0000] {taskinstance.py:3311} ERROR - Task failed with exception
Traceback (most recent call last):
  File "/home/airflow/.local/lib/python3.12/site-packages/airflow/models/taskinstance.py", line 767, in _execute_task
    result = _execute_callable(context=context, **execute_callable_kwargs)
             ^^^^^^^^^^^^^^^^^^^^^^^^^^^^^^^^^^^^^^^^^^^^^^^^^^^^^^^^^^^^^
  File "/home/airflow/.local/lib/python3.12/site-packages/airflow/models/taskinstance.py", line 733, in _execute_callable
    return ExecutionCallableRunner(
           ^^^^^^^^^^^^^^^^^^^^^^^^
  File "/home/airflow/.local/lib/python3.12/site-packages/airflow/utils/operator_helpers.py", line 252, in run
    return self.func(*args, **kwargs)
           ^^^^^^^^^^^^^^^^^^^^^^^^^^
  File "/home/airflow/.local/lib/python3.12/site-packages/airflow/models/baseoperator.py", line 422, in wrapper
    return func(self, *args, **kwargs)
           ^^^^^^^^^^^^^^^^^^^^^^^^^^^
  File "/home/airflow/.local/lib/python3.12/site-packages/airflow/operators/python.py", line 238, in execute
    return_value = self.execute_callable()
                   ^^^^^^^^^^^^^^^^^^^^^^^
  File "/home/airflow/.local/lib/python3.12/site-packages/airflow/operators/python.py", line 256, in execute_callable
    return runner.run(*self.op_args, **self.op_kwargs)
           ^^^^^^^^^^^^^^^^^^^^^^^^^^^^^^^^^^^^^^^^^^^
  File "/home/airflow/.local/lib/python3.12/site-packages/airflow/utils/operator_helpers.py", line 252, in run
    return self.func(*args, **kwargs)
           ^^^^^^^^^^^^^^^^^^^^^^^^^^
  File "/opt/airflow/dags/test_car_5 _tg.py", line 188, in process_file
    raise ValueError(error_msg)
ValueError: Файл cars_20250522.csv не найден в бакете car-prices-bucket
[2025-05-22T10:55:27.625+0000] {taskinstance.py:1225} INFO - Marking task as UP_FOR_RETRY. dag_id=test_car_5_tg, task_id=process_file, run_id=manual__2025-05-22T10:54:53.856104+00:00, execution_date=20250522T105453, start_date=20250522T105520, end_date=20250522T105527
[2025-05-22T10:55:27.689+0000] {taskinstance.py:340} INFO - ::group::Post task execution logs
[2025-05-22T10:55:27.690+0000] {standard_task_runner.py:124} ERROR - Failed to execute job 5 for task process_file (Файл cars_20250522.csv не найден в бакете car-prices-bucket; 254)
Traceback (most recent call last):
  File "/home/airflow/.local/lib/python3.12/site-packages/airflow/task/task_runner/standard_task_runner.py", line 117, in _start_by_fork
    ret = args.func(args, dag=self.dag)
          ^^^^^^^^^^^^^^^^^^^^^^^^^^^^^
  File "/home/airflow/.local/lib/python3.12/site-packages/airflow/cli/cli_config.py", line 49, in command
    return func(*args, **kwargs)
           ^^^^^^^^^^^^^^^^^^^^^
  File "/home/airflow/.local/lib/python3.12/site-packages/airflow/utils/cli.py", line 116, in wrapper
    return f(*args, **kwargs)
           ^^^^^^^^^^^^^^^^^^
  File "/home/airflow/.local/lib/python3.12/site-packages/airflow/cli/commands/task_command.py", line 483, in task_run
    task_return_code = _run_task_by_selected_method(args, _dag, ti)
                       ^^^^^^^^^^^^^^^^^^^^^^^^^^^^^^^^^^^^^^^^^^^^
  File "/home/airflow/.local/lib/python3.12/site-packages/airflow/cli/commands/task_command.py", line 256, in _run_task_by_selected_method
    return _run_raw_task(args, ti)
           ^^^^^^^^^^^^^^^^^^^^^^^
  File "/home/airflow/.local/lib/python3.12/site-packages/airflow/cli/commands/task_command.py", line 341, in _run_raw_task
    return ti._run_raw_task(
           ^^^^^^^^^^^^^^^^^
  File "/home/airflow/.local/lib/python3.12/site-packages/airflow/utils/session.py", line 97, in wrapper
    return func(*args, session=session, **kwargs)
           ^^^^^^^^^^^^^^^^^^^^^^^^^^^^^^^^^^^^^^
  File "/home/airflow/.local/lib/python3.12/site-packages/airflow/models/taskinstance.py", line 3005, in _run_raw_task
    return _run_raw_task(
           ^^^^^^^^^^^^^^
  File "/home/airflow/.local/lib/python3.12/site-packages/airflow/models/taskinstance.py", line 273, in _run_raw_task
    TaskInstance._execute_task_with_callbacks(
  File "/home/airflow/.local/lib/python3.12/site-packages/airflow/models/taskinstance.py", line 3159, in _execute_task_with_callbacks
    result = self._execute_task(context, task_orig)
             ^^^^^^^^^^^^^^^^^^^^^^^^^^^^^^^^^^^^^^
  File "/home/airflow/.local/lib/python3.12/site-packages/airflow/models/taskinstance.py", line 3183, in _execute_task
    return _execute_task(self, context, task_orig)
           ^^^^^^^^^^^^^^^^^^^^^^^^^^^^^^^^^^^^^^^
  File "/home/airflow/.local/lib/python3.12/site-packages/airflow/models/taskinstance.py", line 767, in _execute_task
    result = _execute_callable(context=context, **execute_callable_kwargs)
             ^^^^^^^^^^^^^^^^^^^^^^^^^^^^^^^^^^^^^^^^^^^^^^^^^^^^^^^^^^^^^
  File "/home/airflow/.local/lib/python3.12/site-packages/airflow/models/taskinstance.py", line 733, in _execute_callable
    return ExecutionCallableRunner(
           ^^^^^^^^^^^^^^^^^^^^^^^^
  File "/home/airflow/.local/lib/python3.12/site-packages/airflow/utils/operator_helpers.py", line 252, in run
    return self.func(*args, **kwargs)
           ^^^^^^^^^^^^^^^^^^^^^^^^^^
  File "/home/airflow/.local/lib/python3.12/site-packages/airflow/models/baseoperator.py", line 422, in wrapper
    return func(self, *args, **kwargs)
           ^^^^^^^^^^^^^^^^^^^^^^^^^^^
  File "/home/airflow/.local/lib/python3.12/site-packages/airflow/operators/python.py", line 238, in execute
    return_value = self.execute_callable()
                   ^^^^^^^^^^^^^^^^^^^^^^^
  File "/home/airflow/.local/lib/python3.12/site-packages/airflow/operators/python.py", line 256, in execute_callable
    return runner.run(*self.op_args, **self.op_kwargs)
           ^^^^^^^^^^^^^^^^^^^^^^^^^^^^^^^^^^^^^^^^^^^
  File "/home/airflow/.local/lib/python3.12/site-packages/airflow/utils/operator_helpers.py", line 252, in run
    return self.func(*args, **kwargs)
           ^^^^^^^^^^^^^^^^^^^^^^^^^^
  File "/opt/airflow/dags/test_car_5 _tg.py", line 188, in process_file
    raise ValueError(error_msg)
ValueError: Файл cars_20250522.csv не найден в бакете car-prices-bucket
[2025-05-22T10:55:27.787+0000] {local_task_job_runner.py:266} INFO - Task exited with return code 1
[2025-05-22T10:55:27.820+0000] {taskinstance.py:3895} INFO - 0 downstream tasks scheduled from follow-on schedule check
[2025-05-22T10:55:27.823+0000] {local_task_job_runner.py:245} INFO - ::endgroup::
