[2025-05-21T18:23:06.271+0000] {local_task_job_runner.py:123} INFO - ::group::Pre task execution logs
[2025-05-21T18:23:06.308+0000] {taskinstance.py:2613} INFO - Dependencies all met for dep_context=non-requeueable deps ti=<TaskInstance: test_car_5_tg.process_file manual__2025-05-21T18:23:00.901851+00:00 [queued]>
[2025-05-21T18:23:06.327+0000] {taskinstance.py:2613} INFO - Dependencies all met for dep_context=requeueable deps ti=<TaskInstance: test_car_5_tg.process_file manual__2025-05-21T18:23:00.901851+00:00 [queued]>
[2025-05-21T18:23:06.328+0000] {taskinstance.py:2866} INFO - Starting attempt 1 of 2
[2025-05-21T18:23:06.360+0000] {taskinstance.py:2889} INFO - Executing <Task(PythonOperator): process_file> on 2025-05-21 18:23:00.901851+00:00
[2025-05-21T18:23:06.372+0000] {warnings.py:112} WARNING - /home/***/.local/lib/python3.12/site-packages/***/task/task_runner/standard_task_runner.py:70: DeprecationWarning: This process (pid=1074) is multi-threaded, use of fork() may lead to deadlocks in the child.
  pid = os.fork()

[2025-05-21T18:23:06.374+0000] {standard_task_runner.py:72} INFO - Started process 1076 to run task
[2025-05-21T18:23:06.377+0000] {standard_task_runner.py:104} INFO - Running: ['***', 'tasks', 'run', 'test_car_5_tg', 'process_file', 'manual__2025-05-21T18:23:00.901851+00:00', '--job-id', '14', '--raw', '--subdir', 'DAGS_FOLDER/test_car_5 _tg.py', '--cfg-path', '/tmp/tmpsicgbz_8']
[2025-05-21T18:23:06.382+0000] {standard_task_runner.py:105} INFO - Job 14: Subtask process_file
[2025-05-21T18:23:06.454+0000] {task_command.py:467} INFO - Running <TaskInstance: test_car_5_tg.process_file manual__2025-05-21T18:23:00.901851+00:00 [running]> on host 0562d356b684
[2025-05-21T18:23:06.590+0000] {taskinstance.py:3132} INFO - Exporting env vars: AIRFLOW_CTX_DAG_OWNER='***' AIRFLOW_CTX_DAG_ID='test_car_5_tg' AIRFLOW_CTX_TASK_ID='process_file' AIRFLOW_CTX_EXECUTION_DATE='2025-05-21T18:23:00.901851+00:00' AIRFLOW_CTX_TRY_NUMBER='1' AIRFLOW_CTX_DAG_RUN_ID='manual__2025-05-21T18:23:00.901851+00:00'
[2025-05-21T18:23:06.592+0000] {taskinstance.py:731} INFO - ::endgroup::
[2025-05-21T18:23:06.614+0000] {test_car_5 _tg.py:140} INFO - >>> [START] process_file
[2025-05-21T18:23:06.615+0000] {test_car_5 _tg.py:143} INFO - Execution date: 2025-05-21 18:23:00.901851+00:00
[2025-05-21T18:23:06.790+0000] {base.py:84} INFO - Retrieving connection 'postgres_default'
[2025-05-21T18:23:06.798+0000] {test_car_5 _tg.py:107} ERROR - Error saving rate to DB: relation "cur_rate" does not exist
LINE 2:                             INSERT INTO cur_rate 
                                                ^

[2025-05-21T18:23:06.799+0000] {test_car_5 _tg.py:117} WARNING - Attempt 1 failed to get currency rate: relation "cur_rate" does not exist
LINE 2:                             INSERT INTO cur_rate 
                                                ^

[2025-05-21T18:23:06.800+0000] {test_car_5 _tg.py:119} INFO - Waiting 15 seconds before next attempt...
[2025-05-21T18:23:22.245+0000] {base.py:84} INFO - Retrieving connection 'postgres_default'
[2025-05-21T18:23:22.253+0000] {test_car_5 _tg.py:107} ERROR - Error saving rate to DB: relation "cur_rate" does not exist
LINE 2:                             INSERT INTO cur_rate 
                                                ^

[2025-05-21T18:23:22.255+0000] {test_car_5 _tg.py:117} WARNING - Attempt 2 failed to get currency rate: relation "cur_rate" does not exist
LINE 2:                             INSERT INTO cur_rate 
                                                ^

[2025-05-21T18:23:22.256+0000] {test_car_5 _tg.py:119} INFO - Waiting 15 seconds before next attempt...
[2025-05-21T18:23:37.471+0000] {base.py:84} INFO - Retrieving connection 'postgres_default'
[2025-05-21T18:23:37.505+0000] {test_car_5 _tg.py:107} ERROR - Error saving rate to DB: relation "cur_rate" does not exist
LINE 2:                             INSERT INTO cur_rate 
                                                ^

[2025-05-21T18:23:37.511+0000] {test_car_5 _tg.py:117} WARNING - Attempt 3 failed to get currency rate: relation "cur_rate" does not exist
LINE 2:                             INSERT INTO cur_rate 
                                                ^

[2025-05-21T18:23:37.893+0000] {test_car_5 _tg.py:59} INFO - Telegram notification sent successfully
[2025-05-21T18:23:37.898+0000] {test_car_5 _tg.py:131} ERROR - ⚠️ <b>Ошибка в DAG test_car_5_tg</b>
Не удалось получить курс валют после 3 попыток
Последняя ошибка: relation "cur_rate" does not exist
LINE 2:                             INSERT INTO cur_rate 
                                                ^

Дата выполнения: 2025-05-21 18:23:00.901851+00:00
[2025-05-21T18:23:38.234+0000] {test_car_5 _tg.py:59} INFO - Telegram notification sent successfully
[2025-05-21T18:23:38.236+0000] {test_car_5 _tg.py:196} ERROR - Error in process_file: ⚠️ <b>Ошибка в DAG test_car_5_tg</b>
Не удалось получить курс валют после 3 попыток
Последняя ошибка: relation "cur_rate" does not exist
LINE 2:                             INSERT INTO cur_rate 
                                                ^

Дата выполнения: 2025-05-21 18:23:00.901851+00:00
Traceback (most recent call last):
  File "/opt/airflow/dags/test_car_5 _tg.py", line 146, in process_file
    currency_rate = get_currency_rate(execution_date)
                    ^^^^^^^^^^^^^^^^^^^^^^^^^^^^^^^^^
  File "/opt/airflow/dags/test_car_5 _tg.py", line 132, in get_currency_rate
    raise Exception(error_message)
Exception: ⚠️ <b>Ошибка в DAG test_car_5_tg</b>
Не удалось получить курс валют после 3 попыток
Последняя ошибка: relation "cur_rate" does not exist
LINE 2:                             INSERT INTO cur_rate 
                                                ^

Дата выполнения: 2025-05-21 18:23:00.901851+00:00
[2025-05-21T18:23:38.244+0000] {taskinstance.py:3311} ERROR - Task failed with exception
Traceback (most recent call last):
  File "/home/airflow/.local/lib/python3.12/site-packages/airflow/models/taskinstance.py", line 767, in _execute_task
    result = _execute_callable(context=context, **execute_callable_kwargs)
             ^^^^^^^^^^^^^^^^^^^^^^^^^^^^^^^^^^^^^^^^^^^^^^^^^^^^^^^^^^^^^
  File "/home/airflow/.local/lib/python3.12/site-packages/airflow/models/taskinstance.py", line 733, in _execute_callable
    return ExecutionCallableRunner(
           ^^^^^^^^^^^^^^^^^^^^^^^^
  File "/home/airflow/.local/lib/python3.12/site-packages/airflow/utils/operator_helpers.py", line 252, in run
    return self.func(*args, **kwargs)
           ^^^^^^^^^^^^^^^^^^^^^^^^^^
  File "/home/airflow/.local/lib/python3.12/site-packages/airflow/models/baseoperator.py", line 422, in wrapper
    return func(self, *args, **kwargs)
           ^^^^^^^^^^^^^^^^^^^^^^^^^^^
  File "/home/airflow/.local/lib/python3.12/site-packages/airflow/operators/python.py", line 238, in execute
    return_value = self.execute_callable()
                   ^^^^^^^^^^^^^^^^^^^^^^^
  File "/home/airflow/.local/lib/python3.12/site-packages/airflow/operators/python.py", line 256, in execute_callable
    return runner.run(*self.op_args, **self.op_kwargs)
           ^^^^^^^^^^^^^^^^^^^^^^^^^^^^^^^^^^^^^^^^^^^
  File "/home/airflow/.local/lib/python3.12/site-packages/airflow/utils/operator_helpers.py", line 252, in run
    return self.func(*args, **kwargs)
           ^^^^^^^^^^^^^^^^^^^^^^^^^^
  File "/opt/airflow/dags/test_car_5 _tg.py", line 146, in process_file
    currency_rate = get_currency_rate(execution_date)
                    ^^^^^^^^^^^^^^^^^^^^^^^^^^^^^^^^^
  File "/opt/airflow/dags/test_car_5 _tg.py", line 132, in get_currency_rate
    raise Exception(error_message)
Exception: ⚠️ <b>Ошибка в DAG test_car_5_tg</b>
Не удалось получить курс валют после 3 попыток
Последняя ошибка: relation "cur_rate" does not exist
LINE 2:                             INSERT INTO cur_rate 
                                                ^

Дата выполнения: 2025-05-21 18:23:00.901851+00:00
[2025-05-21T18:23:38.273+0000] {taskinstance.py:1225} INFO - Marking task as UP_FOR_RETRY. dag_id=test_car_5_tg, task_id=process_file, run_id=manual__2025-05-21T18:23:00.901851+00:00, execution_date=20250521T182300, start_date=20250521T182306, end_date=20250521T182338
[2025-05-21T18:23:38.340+0000] {taskinstance.py:340} INFO - ::group::Post task execution logs
[2025-05-21T18:23:38.342+0000] {standard_task_runner.py:124} ERROR - Failed to execute job 14 for task process_file (⚠️ <b>Ошибка в DAG test_car_5_tg</b>
Не удалось получить курс валют после 3 попыток
Последняя ошибка: relation "cur_rate" does not exist
LINE 2:                             INSERT INTO cur_rate 
                                                ^

Дата выполнения: 2025-05-21 18:23:00.901851+00:00; 1076)
Traceback (most recent call last):
  File "/home/airflow/.local/lib/python3.12/site-packages/airflow/task/task_runner/standard_task_runner.py", line 117, in _start_by_fork
    ret = args.func(args, dag=self.dag)
          ^^^^^^^^^^^^^^^^^^^^^^^^^^^^^
  File "/home/airflow/.local/lib/python3.12/site-packages/airflow/cli/cli_config.py", line 49, in command
    return func(*args, **kwargs)
           ^^^^^^^^^^^^^^^^^^^^^
  File "/home/airflow/.local/lib/python3.12/site-packages/airflow/utils/cli.py", line 116, in wrapper
    return f(*args, **kwargs)
           ^^^^^^^^^^^^^^^^^^
  File "/home/airflow/.local/lib/python3.12/site-packages/airflow/cli/commands/task_command.py", line 483, in task_run
    task_return_code = _run_task_by_selected_method(args, _dag, ti)
                       ^^^^^^^^^^^^^^^^^^^^^^^^^^^^^^^^^^^^^^^^^^^^
  File "/home/airflow/.local/lib/python3.12/site-packages/airflow/cli/commands/task_command.py", line 256, in _run_task_by_selected_method
    return _run_raw_task(args, ti)
           ^^^^^^^^^^^^^^^^^^^^^^^
  File "/home/airflow/.local/lib/python3.12/site-packages/airflow/cli/commands/task_command.py", line 341, in _run_raw_task
    return ti._run_raw_task(
           ^^^^^^^^^^^^^^^^^
  File "/home/airflow/.local/lib/python3.12/site-packages/airflow/utils/session.py", line 97, in wrapper
    return func(*args, session=session, **kwargs)
           ^^^^^^^^^^^^^^^^^^^^^^^^^^^^^^^^^^^^^^
  File "/home/airflow/.local/lib/python3.12/site-packages/airflow/models/taskinstance.py", line 3005, in _run_raw_task
    return _run_raw_task(
           ^^^^^^^^^^^^^^
  File "/home/airflow/.local/lib/python3.12/site-packages/airflow/models/taskinstance.py", line 273, in _run_raw_task
    TaskInstance._execute_task_with_callbacks(
  File "/home/airflow/.local/lib/python3.12/site-packages/airflow/models/taskinstance.py", line 3159, in _execute_task_with_callbacks
    result = self._execute_task(context, task_orig)
             ^^^^^^^^^^^^^^^^^^^^^^^^^^^^^^^^^^^^^^
  File "/home/airflow/.local/lib/python3.12/site-packages/airflow/models/taskinstance.py", line 3183, in _execute_task
    return _execute_task(self, context, task_orig)
           ^^^^^^^^^^^^^^^^^^^^^^^^^^^^^^^^^^^^^^^
  File "/home/airflow/.local/lib/python3.12/site-packages/airflow/models/taskinstance.py", line 767, in _execute_task
    result = _execute_callable(context=context, **execute_callable_kwargs)
             ^^^^^^^^^^^^^^^^^^^^^^^^^^^^^^^^^^^^^^^^^^^^^^^^^^^^^^^^^^^^^
  File "/home/airflow/.local/lib/python3.12/site-packages/airflow/models/taskinstance.py", line 733, in _execute_callable
    return ExecutionCallableRunner(
           ^^^^^^^^^^^^^^^^^^^^^^^^
  File "/home/airflow/.local/lib/python3.12/site-packages/airflow/utils/operator_helpers.py", line 252, in run
    return self.func(*args, **kwargs)
           ^^^^^^^^^^^^^^^^^^^^^^^^^^
  File "/home/airflow/.local/lib/python3.12/site-packages/airflow/models/baseoperator.py", line 422, in wrapper
    return func(self, *args, **kwargs)
           ^^^^^^^^^^^^^^^^^^^^^^^^^^^
  File "/home/airflow/.local/lib/python3.12/site-packages/airflow/operators/python.py", line 238, in execute
    return_value = self.execute_callable()
                   ^^^^^^^^^^^^^^^^^^^^^^^
  File "/home/airflow/.local/lib/python3.12/site-packages/airflow/operators/python.py", line 256, in execute_callable
    return runner.run(*self.op_args, **self.op_kwargs)
           ^^^^^^^^^^^^^^^^^^^^^^^^^^^^^^^^^^^^^^^^^^^
  File "/home/airflow/.local/lib/python3.12/site-packages/airflow/utils/operator_helpers.py", line 252, in run
    return self.func(*args, **kwargs)
           ^^^^^^^^^^^^^^^^^^^^^^^^^^
  File "/opt/airflow/dags/test_car_5 _tg.py", line 146, in process_file
    currency_rate = get_currency_rate(execution_date)
                    ^^^^^^^^^^^^^^^^^^^^^^^^^^^^^^^^^
  File "/opt/airflow/dags/test_car_5 _tg.py", line 132, in get_currency_rate
    raise Exception(error_message)
Exception: ⚠️ <b>Ошибка в DAG test_car_5_tg</b>
Не удалось получить курс валют после 3 попыток
Последняя ошибка: relation "cur_rate" does not exist
LINE 2:                             INSERT INTO cur_rate 
                                                ^

Дата выполнения: 2025-05-21 18:23:00.901851+00:00
[2025-05-21T18:23:38.428+0000] {local_task_job_runner.py:266} INFO - Task exited with return code 1
[2025-05-21T18:23:38.477+0000] {taskinstance.py:3895} INFO - 0 downstream tasks scheduled from follow-on schedule check
[2025-05-21T18:23:38.483+0000] {local_task_job_runner.py:245} INFO - ::endgroup::
