[2025-05-21T18:43:10.001+0000] {local_task_job_runner.py:123} INFO - ::group::Pre task execution logs
[2025-05-21T18:43:10.028+0000] {taskinstance.py:2613} INFO - Dependencies all met for dep_context=non-requeueable deps ti=<TaskInstance: test_car_5_tg_err.process_file manual__2025-05-21T18:43:05.875843+00:00 [queued]>
[2025-05-21T18:43:10.045+0000] {taskinstance.py:2613} INFO - Dependencies all met for dep_context=requeueable deps ti=<TaskInstance: test_car_5_tg_err.process_file manual__2025-05-21T18:43:05.875843+00:00 [queued]>
[2025-05-21T18:43:10.046+0000] {taskinstance.py:2866} INFO - Starting attempt 1 of 2
[2025-05-21T18:43:10.074+0000] {taskinstance.py:2889} INFO - Executing <Task(PythonOperator): process_file> on 2025-05-21 18:43:05.875843+00:00
[2025-05-21T18:43:10.087+0000] {warnings.py:112} WARNING - /home/***/.local/lib/python3.12/site-packages/***/task/task_runner/standard_task_runner.py:70: DeprecationWarning: This process (pid=1325) is multi-threaded, use of fork() may lead to deadlocks in the child.
  pid = os.fork()

[2025-05-21T18:43:10.089+0000] {standard_task_runner.py:72} INFO - Started process 1327 to run task
[2025-05-21T18:43:10.093+0000] {standard_task_runner.py:104} INFO - Running: ['***', 'tasks', 'run', 'test_car_5_tg_err', 'process_file', 'manual__2025-05-21T18:43:05.875843+00:00', '--job-id', '20', '--raw', '--subdir', 'DAGS_FOLDER/test_car_5 _tg_err.py', '--cfg-path', '/tmp/tmphjn38_wa']
[2025-05-21T18:43:10.098+0000] {standard_task_runner.py:105} INFO - Job 20: Subtask process_file
[2025-05-21T18:43:10.282+0000] {task_command.py:467} INFO - Running <TaskInstance: test_car_5_tg_err.process_file manual__2025-05-21T18:43:05.875843+00:00 [running]> on host 0562d356b684
[2025-05-21T18:43:10.550+0000] {taskinstance.py:3132} INFO - Exporting env vars: AIRFLOW_CTX_DAG_OWNER='***' AIRFLOW_CTX_DAG_ID='test_car_5_tg_err' AIRFLOW_CTX_TASK_ID='process_file' AIRFLOW_CTX_EXECUTION_DATE='2025-05-21T18:43:05.875843+00:00' AIRFLOW_CTX_TRY_NUMBER='1' AIRFLOW_CTX_DAG_RUN_ID='manual__2025-05-21T18:43:05.875843+00:00'
[2025-05-21T18:43:10.552+0000] {taskinstance.py:731} INFO - ::endgroup::
[2025-05-21T18:43:10.599+0000] {test_car_5 _tg_err.py:167} INFO - >>> [START] process_file
[2025-05-21T18:43:10.601+0000] {test_car_5 _tg_err.py:170} INFO - Execution date: 2025-05-21 18:43:05.875843+00:00
[2025-05-21T18:43:10.861+0000] {test_car_5 _tg_err.py:142} WARNING - Attempt 1 failed to get currency rates: HTTPSConnectionPool(host='www.cbrr.ru', port=443): Max retries exceeded with url: /scripts/XML_daily.asp?date_req=21/05/2025 (Caused by SSLError(SSLCertVerificationError(1, "[SSL: CERTIFICATE_VERIFY_FAILED] certificate verify failed: Hostname mismatch, certificate is not valid for 'www.cbrr.ru'. (_ssl.c:1000)")))
[2025-05-21T18:43:26.034+0000] {test_car_5 _tg_err.py:142} WARNING - Attempt 2 failed to get currency rates: HTTPSConnectionPool(host='www.cbrr.ru', port=443): Max retries exceeded with url: /scripts/XML_daily.asp?date_req=21/05/2025 (Caused by SSLError(SSLCertVerificationError(1, "[SSL: CERTIFICATE_VERIFY_FAILED] certificate verify failed: Hostname mismatch, certificate is not valid for 'www.cbrr.ru'. (_ssl.c:1000)")))
[2025-05-21T18:43:41.235+0000] {test_car_5 _tg_err.py:142} WARNING - Attempt 3 failed to get currency rates: HTTPSConnectionPool(host='www.cbrr.ru', port=443): Max retries exceeded with url: /scripts/XML_daily.asp?date_req=21/05/2025 (Caused by SSLError(SSLCertVerificationError(1, "[SSL: CERTIFICATE_VERIFY_FAILED] certificate verify failed: Hostname mismatch, certificate is not valid for 'www.cbrr.ru'. (_ssl.c:1000)")))
[2025-05-21T18:43:42.054+0000] {test_car_5 _tg_err.py:59} INFO - Telegram notification sent successfully
[2025-05-21T18:43:42.057+0000] {test_car_5 _tg_err.py:158} ERROR - ⚠️ <b>Ошибка в DAG test_car_5_tg</b>
Не удалось получить курсы валют после 3 попыток
Последняя ошибка: HTTPSConnectionPool(host='www.cbrr.ru', port=443): Max retries exceeded with url: /scripts/XML_daily.asp?date_req=21/05/2025 (Caused by SSLError(SSLCertVerificationError(1, "[SSL: CERTIFICATE_VERIFY_FAILED] certificate verify failed: Hostname mismatch, certificate is not valid for 'www.cbrr.ru'. (_ssl.c:1000)")))
Дата выполнения: 2025-05-21 18:43:05.875843+00:00
[2025-05-21T18:43:42.498+0000] {test_car_5 _tg_err.py:59} INFO - Telegram notification sent successfully
[2025-05-21T18:43:42.500+0000] {test_car_5 _tg_err.py:223} ERROR - Error in process_file: ⚠️ <b>Ошибка в DAG test_car_5_tg</b>
Не удалось получить курсы валют после 3 попыток
Последняя ошибка: HTTPSConnectionPool(host='www.cbrr.ru', port=443): Max retries exceeded with url: /scripts/XML_daily.asp?date_req=21/05/2025 (Caused by SSLError(SSLCertVerificationError(1, "[SSL: CERTIFICATE_VERIFY_FAILED] certificate verify failed: Hostname mismatch, certificate is not valid for 'www.cbrr.ru'. (_ssl.c:1000)")))
Дата выполнения: 2025-05-21 18:43:05.875843+00:00
Traceback (most recent call last):
  File "/opt/airflow/dags/test_car_5 _tg_err.py", line 173, in process_file
    currency_rate = get_currency_rate(execution_date)
                    ^^^^^^^^^^^^^^^^^^^^^^^^^^^^^^^^^
  File "/opt/airflow/dags/test_car_5 _tg_err.py", line 159, in get_currency_rate
    raise Exception(error_message)
Exception: ⚠️ <b>Ошибка в DAG test_car_5_tg</b>
Не удалось получить курсы валют после 3 попыток
Последняя ошибка: HTTPSConnectionPool(host='www.cbrr.ru', port=443): Max retries exceeded with url: /scripts/XML_daily.asp?date_req=21/05/2025 (Caused by SSLError(SSLCertVerificationError(1, "[SSL: CERTIFICATE_VERIFY_FAILED] certificate verify failed: Hostname mismatch, certificate is not valid for 'www.cbrr.ru'. (_ssl.c:1000)")))
Дата выполнения: 2025-05-21 18:43:05.875843+00:00
[2025-05-21T18:43:42.514+0000] {taskinstance.py:3311} ERROR - Task failed with exception
Traceback (most recent call last):
  File "/home/airflow/.local/lib/python3.12/site-packages/airflow/models/taskinstance.py", line 767, in _execute_task
    result = _execute_callable(context=context, **execute_callable_kwargs)
             ^^^^^^^^^^^^^^^^^^^^^^^^^^^^^^^^^^^^^^^^^^^^^^^^^^^^^^^^^^^^^
  File "/home/airflow/.local/lib/python3.12/site-packages/airflow/models/taskinstance.py", line 733, in _execute_callable
    return ExecutionCallableRunner(
           ^^^^^^^^^^^^^^^^^^^^^^^^
  File "/home/airflow/.local/lib/python3.12/site-packages/airflow/utils/operator_helpers.py", line 252, in run
    return self.func(*args, **kwargs)
           ^^^^^^^^^^^^^^^^^^^^^^^^^^
  File "/home/airflow/.local/lib/python3.12/site-packages/airflow/models/baseoperator.py", line 422, in wrapper
    return func(self, *args, **kwargs)
           ^^^^^^^^^^^^^^^^^^^^^^^^^^^
  File "/home/airflow/.local/lib/python3.12/site-packages/airflow/operators/python.py", line 238, in execute
    return_value = self.execute_callable()
                   ^^^^^^^^^^^^^^^^^^^^^^^
  File "/home/airflow/.local/lib/python3.12/site-packages/airflow/operators/python.py", line 256, in execute_callable
    return runner.run(*self.op_args, **self.op_kwargs)
           ^^^^^^^^^^^^^^^^^^^^^^^^^^^^^^^^^^^^^^^^^^^
  File "/home/airflow/.local/lib/python3.12/site-packages/airflow/utils/operator_helpers.py", line 252, in run
    return self.func(*args, **kwargs)
           ^^^^^^^^^^^^^^^^^^^^^^^^^^
  File "/opt/airflow/dags/test_car_5 _tg_err.py", line 173, in process_file
    currency_rate = get_currency_rate(execution_date)
                    ^^^^^^^^^^^^^^^^^^^^^^^^^^^^^^^^^
  File "/opt/airflow/dags/test_car_5 _tg_err.py", line 159, in get_currency_rate
    raise Exception(error_message)
Exception: ⚠️ <b>Ошибка в DAG test_car_5_tg</b>
Не удалось получить курсы валют после 3 попыток
Последняя ошибка: HTTPSConnectionPool(host='www.cbrr.ru', port=443): Max retries exceeded with url: /scripts/XML_daily.asp?date_req=21/05/2025 (Caused by SSLError(SSLCertVerificationError(1, "[SSL: CERTIFICATE_VERIFY_FAILED] certificate verify failed: Hostname mismatch, certificate is not valid for 'www.cbrr.ru'. (_ssl.c:1000)")))
Дата выполнения: 2025-05-21 18:43:05.875843+00:00
[2025-05-21T18:43:42.554+0000] {taskinstance.py:1225} INFO - Marking task as UP_FOR_RETRY. dag_id=test_car_5_tg_err, task_id=process_file, run_id=manual__2025-05-21T18:43:05.875843+00:00, execution_date=20250521T184305, start_date=20250521T184310, end_date=20250521T184342
[2025-05-21T18:43:42.594+0000] {taskinstance.py:340} INFO - ::group::Post task execution logs
[2025-05-21T18:43:42.596+0000] {standard_task_runner.py:124} ERROR - Failed to execute job 20 for task process_file (⚠️ <b>Ошибка в DAG test_car_5_tg</b>
Не удалось получить курсы валют после 3 попыток
Последняя ошибка: HTTPSConnectionPool(host='www.cbrr.ru', port=443): Max retries exceeded with url: /scripts/XML_daily.asp?date_req=21/05/2025 (Caused by SSLError(SSLCertVerificationError(1, "[SSL: CERTIFICATE_VERIFY_FAILED] certificate verify failed: Hostname mismatch, certificate is not valid for 'www.cbrr.ru'. (_ssl.c:1000)")))
Дата выполнения: 2025-05-21 18:43:05.875843+00:00; 1327)
Traceback (most recent call last):
  File "/home/airflow/.local/lib/python3.12/site-packages/airflow/task/task_runner/standard_task_runner.py", line 117, in _start_by_fork
    ret = args.func(args, dag=self.dag)
          ^^^^^^^^^^^^^^^^^^^^^^^^^^^^^
  File "/home/airflow/.local/lib/python3.12/site-packages/airflow/cli/cli_config.py", line 49, in command
    return func(*args, **kwargs)
           ^^^^^^^^^^^^^^^^^^^^^
  File "/home/airflow/.local/lib/python3.12/site-packages/airflow/utils/cli.py", line 116, in wrapper
    return f(*args, **kwargs)
           ^^^^^^^^^^^^^^^^^^
  File "/home/airflow/.local/lib/python3.12/site-packages/airflow/cli/commands/task_command.py", line 483, in task_run
    task_return_code = _run_task_by_selected_method(args, _dag, ti)
                       ^^^^^^^^^^^^^^^^^^^^^^^^^^^^^^^^^^^^^^^^^^^^
  File "/home/airflow/.local/lib/python3.12/site-packages/airflow/cli/commands/task_command.py", line 256, in _run_task_by_selected_method
    return _run_raw_task(args, ti)
           ^^^^^^^^^^^^^^^^^^^^^^^
  File "/home/airflow/.local/lib/python3.12/site-packages/airflow/cli/commands/task_command.py", line 341, in _run_raw_task
    return ti._run_raw_task(
           ^^^^^^^^^^^^^^^^^
  File "/home/airflow/.local/lib/python3.12/site-packages/airflow/utils/session.py", line 97, in wrapper
    return func(*args, session=session, **kwargs)
           ^^^^^^^^^^^^^^^^^^^^^^^^^^^^^^^^^^^^^^
  File "/home/airflow/.local/lib/python3.12/site-packages/airflow/models/taskinstance.py", line 3005, in _run_raw_task
    return _run_raw_task(
           ^^^^^^^^^^^^^^
  File "/home/airflow/.local/lib/python3.12/site-packages/airflow/models/taskinstance.py", line 273, in _run_raw_task
    TaskInstance._execute_task_with_callbacks(
  File "/home/airflow/.local/lib/python3.12/site-packages/airflow/models/taskinstance.py", line 3159, in _execute_task_with_callbacks
    result = self._execute_task(context, task_orig)
             ^^^^^^^^^^^^^^^^^^^^^^^^^^^^^^^^^^^^^^
  File "/home/airflow/.local/lib/python3.12/site-packages/airflow/models/taskinstance.py", line 3183, in _execute_task
    return _execute_task(self, context, task_orig)
           ^^^^^^^^^^^^^^^^^^^^^^^^^^^^^^^^^^^^^^^
  File "/home/airflow/.local/lib/python3.12/site-packages/airflow/models/taskinstance.py", line 767, in _execute_task
    result = _execute_callable(context=context, **execute_callable_kwargs)
             ^^^^^^^^^^^^^^^^^^^^^^^^^^^^^^^^^^^^^^^^^^^^^^^^^^^^^^^^^^^^^
  File "/home/airflow/.local/lib/python3.12/site-packages/airflow/models/taskinstance.py", line 733, in _execute_callable
    return ExecutionCallableRunner(
           ^^^^^^^^^^^^^^^^^^^^^^^^
  File "/home/airflow/.local/lib/python3.12/site-packages/airflow/utils/operator_helpers.py", line 252, in run
    return self.func(*args, **kwargs)
           ^^^^^^^^^^^^^^^^^^^^^^^^^^
  File "/home/airflow/.local/lib/python3.12/site-packages/airflow/models/baseoperator.py", line 422, in wrapper
    return func(self, *args, **kwargs)
           ^^^^^^^^^^^^^^^^^^^^^^^^^^^
  File "/home/airflow/.local/lib/python3.12/site-packages/airflow/operators/python.py", line 238, in execute
    return_value = self.execute_callable()
                   ^^^^^^^^^^^^^^^^^^^^^^^
  File "/home/airflow/.local/lib/python3.12/site-packages/airflow/operators/python.py", line 256, in execute_callable
    return runner.run(*self.op_args, **self.op_kwargs)
           ^^^^^^^^^^^^^^^^^^^^^^^^^^^^^^^^^^^^^^^^^^^
  File "/home/airflow/.local/lib/python3.12/site-packages/airflow/utils/operator_helpers.py", line 252, in run
    return self.func(*args, **kwargs)
           ^^^^^^^^^^^^^^^^^^^^^^^^^^
  File "/opt/airflow/dags/test_car_5 _tg_err.py", line 173, in process_file
    currency_rate = get_currency_rate(execution_date)
                    ^^^^^^^^^^^^^^^^^^^^^^^^^^^^^^^^^
  File "/opt/airflow/dags/test_car_5 _tg_err.py", line 159, in get_currency_rate
    raise Exception(error_message)
Exception: ⚠️ <b>Ошибка в DAG test_car_5_tg</b>
Не удалось получить курсы валют после 3 попыток
Последняя ошибка: HTTPSConnectionPool(host='www.cbrr.ru', port=443): Max retries exceeded with url: /scripts/XML_daily.asp?date_req=21/05/2025 (Caused by SSLError(SSLCertVerificationError(1, "[SSL: CERTIFICATE_VERIFY_FAILED] certificate verify failed: Hostname mismatch, certificate is not valid for 'www.cbrr.ru'. (_ssl.c:1000)")))
Дата выполнения: 2025-05-21 18:43:05.875843+00:00
[2025-05-21T18:43:42.633+0000] {local_task_job_runner.py:266} INFO - Task exited with return code 1
[2025-05-21T18:43:42.668+0000] {local_task_job_runner.py:245} INFO - ::endgroup::
